<?xml version="1.0" ?>
<!-- =================================================================================== -->
<!-- |    This document was autogenerated by xacro from hit2.urdf.xacro                | -->
<!-- |    EDITING THIS FILE BY HAND IS NOT RECOMMENDED                                 | -->
<!-- =================================================================================== -->
<robot name="dlr_hit2" xmlns:xacro="http://www.ros.org/wiki/xacro">
  <!-- <robot xmlns:sensor="http://playerstage.sourceforge.net/gazebo/xmlschema/#sensor"
       xmlns:controller="http://playerstage.sourceforge.net/gazebo/xmlschema/#controller"
       xmlns:interface="http://playerstage.sourceforge.net/gazebo/xmlschema/#interface"
       xmlns:xacro="http://ros.org/wiki/xacro"> -->
  <material name="DLR/LightGrey">
    <color rgba="0.7 0.7 0.7 1.0"/>
  </material>
  <material name="DLR/DarkGrey">
    <color rgba="0.4 0.4 0.4 1.0"/>
  </material>
  <material name="DLR/Black">
    <color rgba="0.0 0.0 0.0 1.0"/>
  </material>
  <material name="DLR/DarkGolden">
    <color rgba="0.4 0.4 0.3 1.0"/>
  </material>
  <material name="DLR/Blue">
    <color rgba="0.0 0.0 0.8 1.0"/>
  </material>
  <link name="world_link">
    <inertial>
      <mass value="50.0"/>
      <com xyz="0 0 0"/>
      <inertia ixx="0.01" ixy="0.00" ixz="0.00" iyy="0.01" iyz="0.00" izz="0.01"/>
    </inertial>
    <visual>
      <origin rpy="0 0 0" xyz="0 0 0.50"/>
      <geometry>
        <box size="1 1 1.0"/>
      </geometry>
    </visual>
    <collision>
      <origin rpy="0 0 0" xyz="0 0 0.50"/>
      <geometry>
        <box size="1 1 1.0"/>
      </geometry>
    </collision>
  </link>
  <!-- macro for the hand -->
  <!-- joint between arm_end_effector and hit2_palm_link -->
  <joint name="right_palm_joint" type="fixed">
    <origin rpy="0 0 0" xyz="0 0 1.0"/>
    <parent link="world_link"/>
    <child link="right_palm_link"/>
  </joint>
  <link name="right_palm_link">
    <!-- <inertial> -->
    <!-- PALM MASS AND INERTIA TO BE ESTIMATED!!!! -->
    <!-- <origin xyz="0 0 0" rpy="0 0 0"/>
				<mass value="1"/>
				<inertia ixx="0.01" ixy="0" ixz="0" iyy="0.01" iyz="0" izz="0.01" />
			</inertial> -->
    <!-- also check whether is ok to leave at zero the origin -->
    <visual>
      <origin rpy="0 0 0" xyz="0 0 0"/>
      <geometry>
        <mesh filename="package://dlr_description/meshes/hit2/palm.stl"/>
      </geometry>
      <material name="DLR/LightGrey"/>
    </visual>
    <collision>
      <origin rpy="0 0 0" xyz="0 0 0"/>
      <geometry>
        <mesh filename="package://dlr_description/meshes/hit2/palm.stl"/>
      </geometry>
    </collision>
  </link>
  <!-- macro for one finger -->
  <!-- abductor joint between palm_link and finger_abd_link - fake between palm and proximal -->
  <joint name="right_thumb_abd_joint" type="revolute">
    <origin rpy="0.41136 -1.08366 0.225804" xyz="0.062569057 0.044544548 0.080044647"/>
    <parent link="right_palm_link"/>
    <child link="right_thumb_abd_link"/>
    <axis xyz="0 0 1"/>
    <dynamics damping="1"/>
    <limit effort="100" lower="-0.349065850399" upper="0.349065850399" velocity="5"/>
    <!-- effort="100" velocity="5" -->
  </joint>
  <link name="right_thumb_abd_link">
    <!-- 			<inertial>
				<origin xyz="0 0 0" rpy="0 0 0"/>
				<mass value="0.0"/>
				<inertia ixx="0" ixy="0" ixz="0" iyy="0" iyz="0" izz="0" />
			</inertial> -->
    <!-- possibly add basecover.stl as both geometry and collision... -->
    <visual>
      <origin rpy="0 0 0" xyz="0 0 0"/>
      <geometry>
        <mesh filename="package://dlr_description/meshes/hit2/base.stl"/>
      </geometry>
      <material name="DLR/LightGrey"/>
    </visual>
  </link>
  <!-- inner joint between abd_link and proximal_link -->
  <joint name="right_thumb_inner_joint" type="revolute">
    <!-- coincident with abd_joint, rotated of 90 degrees along x -->
    <origin rpy="1.57079632679 0 0" xyz="0 0 0"/>
    <parent link="right_thumb_abd_link"/>
    <child link="right_thumb_proximal_link"/>
    <axis xyz="0 0 1"/>
    <dynamics damping="1"/>
    <limit effort="100" lower="0.0" upper="1.308996939" velocity="5"/>
    <!-- effort="100" velocity="5" -->
  </joint>
  <link name="right_thumb_proximal_link">
    <!-- <inertial>
				<origin xyz="30.164510e -1.0130813 0.50813186" rpy="0 0 0"/>
				<mass value="0.044370598"/>
				<inertia ixx="${inertia_scale * 4.5592704}" ixy="${inertia_scale * 0.90783105}" ixz="${inertia_scale * (-0.9399771)}" iyy="${inertia_scale * 49.045259}" iyz="${inertia_scale * 0.017052714}" izz="${inertia_scale * 50.524234}" />
			</inertial> -->
    <visual>
      <origin rpy="0 0 0" xyz="0 0 0"/>
      <geometry>
        <mesh filename="package://dlr_description/meshes/hit2/proximal.stl"/>
      </geometry>
      <material name="DLR/LightGrey"/>
    </visual>
    <!-- 			<collision>
				<origin xyz="0 0 0" rpy="0 0 0" />
				<geometry>
					<mesh filename="package://dlr_description/meshes/hit2/phalanx_proximal.stl"/>
				</geometry>
			</collision> -->
  </link>
  <!-- outer1 joint between proximal_link and medial_link -->
  <joint name="right_thumb_outer1_joint" type="revolute">
    <origin rpy="0 0 0" xyz="0.055 0 0"/>
    <parent link="right_thumb_proximal_link"/>
    <child link="right_thumb_medial_link"/>
    <axis xyz="0 0 1"/>
    <dynamics damping="1"/>
    <limit effort="100" lower="0.0" upper="1.308996939" velocity="5"/>
    <!-- effort="100" velocity="5" -->
  </joint>
  <link name="right_thumb_medial_link">
    <!-- <inertial>
			<origin xyz="5.7271879 -1.6164173 -1.1567914" rpy="0 0 0"/>
				<mass value="0.027110192"/>
				<inertia ixx="${inertia_scale * 2.2900229}" ixy="${inertia_scale * 0.40604622}" ixz="${inertia_scale * 0.14362094}" iyy="${inertia_scale * 4.2155489}" iyz="${inertia_scale * (-0.043115648)}" izz="${inertia_scale * 4.4292927}" />
			</inertial> -->
    <visual>
      <origin rpy="0 0 0" xyz="0 0 0"/>
      <geometry>
        <mesh filename="package://dlr_description/meshes/hit2/medial.stl"/>
      </geometry>
      <material name="DLR/LightGrey"/>
    </visual>
    <collision>
      <origin rpy="0 0 0" xyz="0 0 0"/>
      <geometry>
        <mesh filename="package://dlr_description/meshes/hit2/medial.stl"/>
      </geometry>
    </collision>
  </link>
  <!-- outer2 joint between medial_link and distal_link -->
  <joint name="right_thumb_outer2_joint" type="revolute">
    <origin rpy="0 0 -1.57079632679" xyz="0.025 0 0"/>
    <parent link="right_thumb_medial_link"/>
    <child link="right_thumb_distal_link"/>
    <axis xyz="0 0 1"/>
    <dynamics damping="1"/>
    <limit effort="100" lower="0.0" upper="1.308996939" velocity="5"/>
    <!-- effort="100" velocity="5" -->
  </joint>
  <link name="right_thumb_distal_link">
    <!-- <inertial>
			<origin xyz="-0.83348211 6.1007977 1.7728256" rpy="0 0 0"/>
				<mass value="0.018179709"/>
				<inertia ixx="${inertia_scale * 2.5867271}" ixy="${inertia_scale * 0.15840536}" ixz="${inertia_scale * (-0.00078205885)}" iyy="${inertia_scale * 0.84596248}" iyz="${inertia_scale * (-0.0048358115)}" izz="${inertia_scale * 2.5838485}" />
			</inertial> -->
    <visual>
      <origin rpy="0 0 0" xyz="0 0 0"/>
      <geometry>
        <mesh filename="package://dlr_description/meshes/hit2/distal.stl"/>
      </geometry>
      <material name="DLR/LightGrey"/>
    </visual>
    <collision>
      <origin rpy="0 0 0" xyz="0 0 0"/>
      <geometry>
        <mesh filename="package://dlr_description/meshes/hit2/distal.stl"/>
      </geometry>
    </collision>
  </link>
  <!-- macro for one finger -->
  <!-- abductor joint between palm_link and finger_abd_link - fake between palm and proximal -->
  <joint name="right_index_abd_joint" type="revolute">
    <origin rpy="3.05433 -1.57079632679 0" xyz="-0.002529881 0.036800135 0.108743545"/>
    <parent link="right_palm_link"/>
    <child link="right_index_abd_link"/>
    <axis xyz="0 0 1"/>
    <dynamics damping="1"/>
    <limit effort="100" lower="-0.349065850399" upper="0.349065850399" velocity="5"/>
    <!-- effort="100" velocity="5" -->
  </joint>
  <link name="right_index_abd_link">
    <!-- 			<inertial>
				<origin xyz="0 0 0" rpy="0 0 0"/>
				<mass value="0.0"/>
				<inertia ixx="0" ixy="0" ixz="0" iyy="0" iyz="0" izz="0" />
			</inertial> -->
    <!-- possibly add basecover.stl as both geometry and collision... -->
    <visual>
      <origin rpy="0 0 0" xyz="0 0 0"/>
      <geometry>
        <mesh filename="package://dlr_description/meshes/hit2/base.stl"/>
      </geometry>
      <material name="DLR/LightGrey"/>
    </visual>
  </link>
  <!-- inner joint between abd_link and proximal_link -->
  <joint name="right_index_inner_joint" type="revolute">
    <!-- coincident with abd_joint, rotated of 90 degrees along x -->
    <origin rpy="1.57079632679 0 0" xyz="0 0 0"/>
    <parent link="right_index_abd_link"/>
    <child link="right_index_proximal_link"/>
    <axis xyz="0 0 1"/>
    <dynamics damping="1"/>
    <limit effort="100" lower="0.0" upper="1.308996939" velocity="5"/>
    <!-- effort="100" velocity="5" -->
  </joint>
  <link name="right_index_proximal_link">
    <!-- <inertial>
				<origin xyz="30.164510e -1.0130813 0.50813186" rpy="0 0 0"/>
				<mass value="0.044370598"/>
				<inertia ixx="${inertia_scale * 4.5592704}" ixy="${inertia_scale * 0.90783105}" ixz="${inertia_scale * (-0.9399771)}" iyy="${inertia_scale * 49.045259}" iyz="${inertia_scale * 0.017052714}" izz="${inertia_scale * 50.524234}" />
			</inertial> -->
    <visual>
      <origin rpy="0 0 0" xyz="0 0 0"/>
      <geometry>
        <mesh filename="package://dlr_description/meshes/hit2/proximal.stl"/>
      </geometry>
      <material name="DLR/LightGrey"/>
    </visual>
    <!-- 			<collision>
				<origin xyz="0 0 0" rpy="0 0 0" />
				<geometry>
					<mesh filename="package://dlr_description/meshes/hit2/phalanx_proximal.stl"/>
				</geometry>
			</collision> -->
  </link>
  <!-- outer1 joint between proximal_link and medial_link -->
  <joint name="right_index_outer1_joint" type="revolute">
    <origin rpy="0 0 0" xyz="0.055 0 0"/>
    <parent link="right_index_proximal_link"/>
    <child link="right_index_medial_link"/>
    <axis xyz="0 0 1"/>
    <dynamics damping="1"/>
    <limit effort="100" lower="0.0" upper="1.308996939" velocity="5"/>
    <!-- effort="100" velocity="5" -->
  </joint>
  <link name="right_index_medial_link">
    <!-- <inertial>
			<origin xyz="5.7271879 -1.6164173 -1.1567914" rpy="0 0 0"/>
				<mass value="0.027110192"/>
				<inertia ixx="${inertia_scale * 2.2900229}" ixy="${inertia_scale * 0.40604622}" ixz="${inertia_scale * 0.14362094}" iyy="${inertia_scale * 4.2155489}" iyz="${inertia_scale * (-0.043115648)}" izz="${inertia_scale * 4.4292927}" />
			</inertial> -->
    <visual>
      <origin rpy="0 0 0" xyz="0 0 0"/>
      <geometry>
        <mesh filename="package://dlr_description/meshes/hit2/medial.stl"/>
      </geometry>
      <material name="DLR/LightGrey"/>
    </visual>
    <collision>
      <origin rpy="0 0 0" xyz="0 0 0"/>
      <geometry>
        <mesh filename="package://dlr_description/meshes/hit2/medial.stl"/>
      </geometry>
    </collision>
  </link>
  <!-- outer2 joint between medial_link and distal_link -->
  <joint name="right_index_outer2_joint" type="revolute">
    <origin rpy="0 0 -1.57079632679" xyz="0.025 0 0"/>
    <parent link="right_index_medial_link"/>
    <child link="right_index_distal_link"/>
    <axis xyz="0 0 1"/>
    <dynamics damping="1"/>
    <limit effort="100" lower="0.0" upper="1.308996939" velocity="5"/>
    <!-- effort="100" velocity="5" -->
  </joint>
  <link name="right_index_distal_link">
    <!-- <inertial>
			<origin xyz="-0.83348211 6.1007977 1.7728256" rpy="0 0 0"/>
				<mass value="0.018179709"/>
				<inertia ixx="${inertia_scale * 2.5867271}" ixy="${inertia_scale * 0.15840536}" ixz="${inertia_scale * (-0.00078205885)}" iyy="${inertia_scale * 0.84596248}" iyz="${inertia_scale * (-0.0048358115)}" izz="${inertia_scale * 2.5838485}" />
			</inertial> -->
    <visual>
      <origin rpy="0 0 0" xyz="0 0 0"/>
      <geometry>
        <mesh filename="package://dlr_description/meshes/hit2/distal.stl"/>
      </geometry>
      <material name="DLR/LightGrey"/>
    </visual>
    <collision>
      <origin rpy="0 0 0" xyz="0 0 0"/>
      <geometry>
        <mesh filename="package://dlr_description/meshes/hit2/distal.stl"/>
      </geometry>
    </collision>
  </link>
  <!-- macro for one finger -->
  <!-- abductor joint between palm_link and finger_abd_link - fake between palm and proximal -->
  <joint name="right_middle_abd_joint" type="revolute">
    <origin rpy="3.14159265359 -1.57079632679 0" xyz="-0.0037 0.01 0.119043545"/>
    <parent link="right_palm_link"/>
    <child link="right_middle_abd_link"/>
    <axis xyz="0 0 1"/>
    <dynamics damping="1"/>
    <limit effort="100" lower="-0.349065850399" upper="0.349065850399" velocity="5"/>
    <!-- effort="100" velocity="5" -->
  </joint>
  <link name="right_middle_abd_link">
    <!-- 			<inertial>
				<origin xyz="0 0 0" rpy="0 0 0"/>
				<mass value="0.0"/>
				<inertia ixx="0" ixy="0" ixz="0" iyy="0" iyz="0" izz="0" />
			</inertial> -->
    <!-- possibly add basecover.stl as both geometry and collision... -->
    <visual>
      <origin rpy="0 0 0" xyz="0 0 0"/>
      <geometry>
        <mesh filename="package://dlr_description/meshes/hit2/base.stl"/>
      </geometry>
      <material name="DLR/LightGrey"/>
    </visual>
  </link>
  <!-- inner joint between abd_link and proximal_link -->
  <joint name="right_middle_inner_joint" type="revolute">
    <!-- coincident with abd_joint, rotated of 90 degrees along x -->
    <origin rpy="1.57079632679 0 0" xyz="0 0 0"/>
    <parent link="right_middle_abd_link"/>
    <child link="right_middle_proximal_link"/>
    <axis xyz="0 0 1"/>
    <dynamics damping="1"/>
    <limit effort="100" lower="0.0" upper="1.308996939" velocity="5"/>
    <!-- effort="100" velocity="5" -->
  </joint>
  <link name="right_middle_proximal_link">
    <!-- <inertial>
				<origin xyz="30.164510e -1.0130813 0.50813186" rpy="0 0 0"/>
				<mass value="0.044370598"/>
				<inertia ixx="${inertia_scale * 4.5592704}" ixy="${inertia_scale * 0.90783105}" ixz="${inertia_scale * (-0.9399771)}" iyy="${inertia_scale * 49.045259}" iyz="${inertia_scale * 0.017052714}" izz="${inertia_scale * 50.524234}" />
			</inertial> -->
    <visual>
      <origin rpy="0 0 0" xyz="0 0 0"/>
      <geometry>
        <mesh filename="package://dlr_description/meshes/hit2/proximal.stl"/>
      </geometry>
      <material name="DLR/LightGrey"/>
    </visual>
    <!-- 			<collision>
				<origin xyz="0 0 0" rpy="0 0 0" />
				<geometry>
					<mesh filename="package://dlr_description/meshes/hit2/phalanx_proximal.stl"/>
				</geometry>
			</collision> -->
  </link>
  <!-- outer1 joint between proximal_link and medial_link -->
  <joint name="right_middle_outer1_joint" type="revolute">
    <origin rpy="0 0 0" xyz="0.055 0 0"/>
    <parent link="right_middle_proximal_link"/>
    <child link="right_middle_medial_link"/>
    <axis xyz="0 0 1"/>
    <dynamics damping="1"/>
    <limit effort="100" lower="0.0" upper="1.308996939" velocity="5"/>
    <!-- effort="100" velocity="5" -->
  </joint>
  <link name="right_middle_medial_link">
    <!-- <inertial>
			<origin xyz="5.7271879 -1.6164173 -1.1567914" rpy="0 0 0"/>
				<mass value="0.027110192"/>
				<inertia ixx="${inertia_scale * 2.2900229}" ixy="${inertia_scale * 0.40604622}" ixz="${inertia_scale * 0.14362094}" iyy="${inertia_scale * 4.2155489}" iyz="${inertia_scale * (-0.043115648)}" izz="${inertia_scale * 4.4292927}" />
			</inertial> -->
    <visual>
      <origin rpy="0 0 0" xyz="0 0 0"/>
      <geometry>
        <mesh filename="package://dlr_description/meshes/hit2/medial.stl"/>
      </geometry>
      <material name="DLR/LightGrey"/>
    </visual>
    <collision>
      <origin rpy="0 0 0" xyz="0 0 0"/>
      <geometry>
        <mesh filename="package://dlr_description/meshes/hit2/medial.stl"/>
      </geometry>
    </collision>
  </link>
  <!-- outer2 joint between medial_link and distal_link -->
  <joint name="right_middle_outer2_joint" type="revolute">
    <origin rpy="0 0 -1.57079632679" xyz="0.025 0 0"/>
    <parent link="right_middle_medial_link"/>
    <child link="right_middle_distal_link"/>
    <axis xyz="0 0 1"/>
    <dynamics damping="1"/>
    <limit effort="100" lower="0.0" upper="1.308996939" velocity="5"/>
    <!-- effort="100" velocity="5" -->
  </joint>
  <link name="right_middle_distal_link">
    <!-- <inertial>
			<origin xyz="-0.83348211 6.1007977 1.7728256" rpy="0 0 0"/>
				<mass value="0.018179709"/>
				<inertia ixx="${inertia_scale * 2.5867271}" ixy="${inertia_scale * 0.15840536}" ixz="${inertia_scale * (-0.00078205885)}" iyy="${inertia_scale * 0.84596248}" iyz="${inertia_scale * (-0.0048358115)}" izz="${inertia_scale * 2.5838485}" />
			</inertial> -->
    <visual>
      <origin rpy="0 0 0" xyz="0 0 0"/>
      <geometry>
        <mesh filename="package://dlr_description/meshes/hit2/distal.stl"/>
      </geometry>
      <material name="DLR/LightGrey"/>
    </visual>
    <collision>
      <origin rpy="0 0 0" xyz="0 0 0"/>
      <geometry>
        <mesh filename="package://dlr_description/meshes/hit2/distal.stl"/>
      </geometry>
    </collision>
  </link>
  <!-- macro for one finger -->
  <!-- abductor joint between palm_link and finger_abd_link - fake between palm and proximal -->
  <joint name="right_ring_abd_joint" type="revolute">
    <origin rpy="-3.05433 -1.57079632679 0" xyz="-0.002529881 -0.016800135 0.114043545"/>
    <parent link="right_palm_link"/>
    <child link="right_ring_abd_link"/>
    <axis xyz="0 0 1"/>
    <dynamics damping="1"/>
    <limit effort="100" lower="-0.349065850399" upper="0.349065850399" velocity="5"/>
    <!-- effort="100" velocity="5" -->
  </joint>
  <link name="right_ring_abd_link">
    <!-- 			<inertial>
				<origin xyz="0 0 0" rpy="0 0 0"/>
				<mass value="0.0"/>
				<inertia ixx="0" ixy="0" ixz="0" iyy="0" iyz="0" izz="0" />
			</inertial> -->
    <!-- possibly add basecover.stl as both geometry and collision... -->
    <visual>
      <origin rpy="0 0 0" xyz="0 0 0"/>
      <geometry>
        <mesh filename="package://dlr_description/meshes/hit2/base.stl"/>
      </geometry>
      <material name="DLR/LightGrey"/>
    </visual>
  </link>
  <!-- inner joint between abd_link and proximal_link -->
  <joint name="right_ring_inner_joint" type="revolute">
    <!-- coincident with abd_joint, rotated of 90 degrees along x -->
    <origin rpy="1.57079632679 0 0" xyz="0 0 0"/>
    <parent link="right_ring_abd_link"/>
    <child link="right_ring_proximal_link"/>
    <axis xyz="0 0 1"/>
    <dynamics damping="1"/>
    <limit effort="100" lower="0.0" upper="1.308996939" velocity="5"/>
    <!-- effort="100" velocity="5" -->
  </joint>
  <link name="right_ring_proximal_link">
    <!-- <inertial>
				<origin xyz="30.164510e -1.0130813 0.50813186" rpy="0 0 0"/>
				<mass value="0.044370598"/>
				<inertia ixx="${inertia_scale * 4.5592704}" ixy="${inertia_scale * 0.90783105}" ixz="${inertia_scale * (-0.9399771)}" iyy="${inertia_scale * 49.045259}" iyz="${inertia_scale * 0.017052714}" izz="${inertia_scale * 50.524234}" />
			</inertial> -->
    <visual>
      <origin rpy="0 0 0" xyz="0 0 0"/>
      <geometry>
        <mesh filename="package://dlr_description/meshes/hit2/proximal.stl"/>
      </geometry>
      <material name="DLR/LightGrey"/>
    </visual>
    <!-- 			<collision>
				<origin xyz="0 0 0" rpy="0 0 0" />
				<geometry>
					<mesh filename="package://dlr_description/meshes/hit2/phalanx_proximal.stl"/>
				</geometry>
			</collision> -->
  </link>
  <!-- outer1 joint between proximal_link and medial_link -->
  <joint name="right_ring_outer1_joint" type="revolute">
    <origin rpy="0 0 0" xyz="0.055 0 0"/>
    <parent link="right_ring_proximal_link"/>
    <child link="right_ring_medial_link"/>
    <axis xyz="0 0 1"/>
    <dynamics damping="1"/>
    <limit effort="100" lower="0.0" upper="1.308996939" velocity="5"/>
    <!-- effort="100" velocity="5" -->
  </joint>
  <link name="right_ring_medial_link">
    <!-- <inertial>
			<origin xyz="5.7271879 -1.6164173 -1.1567914" rpy="0 0 0"/>
				<mass value="0.027110192"/>
				<inertia ixx="${inertia_scale * 2.2900229}" ixy="${inertia_scale * 0.40604622}" ixz="${inertia_scale * 0.14362094}" iyy="${inertia_scale * 4.2155489}" iyz="${inertia_scale * (-0.043115648)}" izz="${inertia_scale * 4.4292927}" />
			</inertial> -->
    <visual>
      <origin rpy="0 0 0" xyz="0 0 0"/>
      <geometry>
        <mesh filename="package://dlr_description/meshes/hit2/medial.stl"/>
      </geometry>
      <material name="DLR/LightGrey"/>
    </visual>
    <collision>
      <origin rpy="0 0 0" xyz="0 0 0"/>
      <geometry>
        <mesh filename="package://dlr_description/meshes/hit2/medial.stl"/>
      </geometry>
    </collision>
  </link>
  <!-- outer2 joint between medial_link and distal_link -->
  <joint name="right_ring_outer2_joint" type="revolute">
    <origin rpy="0 0 -1.57079632679" xyz="0.025 0 0"/>
    <parent link="right_ring_medial_link"/>
    <child link="right_ring_distal_link"/>
    <axis xyz="0 0 1"/>
    <dynamics damping="1"/>
    <limit effort="100" lower="0.0" upper="1.308996939" velocity="5"/>
    <!-- effort="100" velocity="5" -->
  </joint>
  <link name="right_ring_distal_link">
    <!-- <inertial>
			<origin xyz="-0.83348211 6.1007977 1.7728256" rpy="0 0 0"/>
				<mass value="0.018179709"/>
				<inertia ixx="${inertia_scale * 2.5867271}" ixy="${inertia_scale * 0.15840536}" ixz="${inertia_scale * (-0.00078205885)}" iyy="${inertia_scale * 0.84596248}" iyz="${inertia_scale * (-0.0048358115)}" izz="${inertia_scale * 2.5838485}" />
			</inertial> -->
    <visual>
      <origin rpy="0 0 0" xyz="0 0 0"/>
      <geometry>
        <mesh filename="package://dlr_description/meshes/hit2/distal.stl"/>
      </geometry>
      <material name="DLR/LightGrey"/>
    </visual>
    <collision>
      <origin rpy="0 0 0" xyz="0 0 0"/>
      <geometry>
        <mesh filename="package://dlr_description/meshes/hit2/distal.stl"/>
      </geometry>
    </collision>
  </link>
  <!-- macro for one finger -->
  <!-- abductor joint between palm_link and finger_abd_link - fake between palm and proximal -->
  <joint name="right_pinky_abd_joint" type="revolute">
    <origin rpy="-2.96706 -1.57079632679 0" xyz="0.000971571 -0.043396306 0.095043545"/>
    <parent link="right_palm_link"/>
    <child link="right_pinky_abd_link"/>
    <axis xyz="0 0 1"/>
    <dynamics damping="1"/>
    <limit effort="100" lower="-0.349065850399" upper="0.349065850399" velocity="5"/>
    <!-- effort="100" velocity="5" -->
  </joint>
  <link name="right_pinky_abd_link">
    <!-- 			<inertial>
				<origin xyz="0 0 0" rpy="0 0 0"/>
				<mass value="0.0"/>
				<inertia ixx="0" ixy="0" ixz="0" iyy="0" iyz="0" izz="0" />
			</inertial> -->
    <!-- possibly add basecover.stl as both geometry and collision... -->
    <visual>
      <origin rpy="0 0 0" xyz="0 0 0"/>
      <geometry>
        <mesh filename="package://dlr_description/meshes/hit2/base.stl"/>
      </geometry>
      <material name="DLR/LightGrey"/>
    </visual>
  </link>
  <!-- inner joint between abd_link and proximal_link -->
  <joint name="right_pinky_inner_joint" type="revolute">
    <!-- coincident with abd_joint, rotated of 90 degrees along x -->
    <origin rpy="1.57079632679 0 0" xyz="0 0 0"/>
    <parent link="right_pinky_abd_link"/>
    <child link="right_pinky_proximal_link"/>
    <axis xyz="0 0 1"/>
    <dynamics damping="1"/>
    <limit effort="100" lower="0.0" upper="1.308996939" velocity="5"/>
    <!-- effort="100" velocity="5" -->
  </joint>
  <link name="right_pinky_proximal_link">
    <!-- <inertial>
				<origin xyz="30.164510e -1.0130813 0.50813186" rpy="0 0 0"/>
				<mass value="0.044370598"/>
				<inertia ixx="${inertia_scale * 4.5592704}" ixy="${inertia_scale * 0.90783105}" ixz="${inertia_scale * (-0.9399771)}" iyy="${inertia_scale * 49.045259}" iyz="${inertia_scale * 0.017052714}" izz="${inertia_scale * 50.524234}" />
			</inertial> -->
    <visual>
      <origin rpy="0 0 0" xyz="0 0 0"/>
      <geometry>
        <mesh filename="package://dlr_description/meshes/hit2/proximal.stl"/>
      </geometry>
      <material name="DLR/LightGrey"/>
    </visual>
    <!-- 			<collision>
				<origin xyz="0 0 0" rpy="0 0 0" />
				<geometry>
					<mesh filename="package://dlr_description/meshes/hit2/phalanx_proximal.stl"/>
				</geometry>
			</collision> -->
  </link>
  <!-- outer1 joint between proximal_link and medial_link -->
  <joint name="right_pinky_outer1_joint" type="revolute">
    <origin rpy="0 0 0" xyz="0.055 0 0"/>
    <parent link="right_pinky_proximal_link"/>
    <child link="right_pinky_medial_link"/>
    <axis xyz="0 0 1"/>
    <dynamics damping="1"/>
    <limit effort="100" lower="0.0" upper="1.308996939" velocity="5"/>
    <!-- effort="100" velocity="5" -->
  </joint>
  <link name="right_pinky_medial_link">
    <!-- <inertial>
			<origin xyz="5.7271879 -1.6164173 -1.1567914" rpy="0 0 0"/>
				<mass value="0.027110192"/>
				<inertia ixx="${inertia_scale * 2.2900229}" ixy="${inertia_scale * 0.40604622}" ixz="${inertia_scale * 0.14362094}" iyy="${inertia_scale * 4.2155489}" iyz="${inertia_scale * (-0.043115648)}" izz="${inertia_scale * 4.4292927}" />
			</inertial> -->
    <visual>
      <origin rpy="0 0 0" xyz="0 0 0"/>
      <geometry>
        <mesh filename="package://dlr_description/meshes/hit2/medial.stl"/>
      </geometry>
      <material name="DLR/LightGrey"/>
    </visual>
    <collision>
      <origin rpy="0 0 0" xyz="0 0 0"/>
      <geometry>
        <mesh filename="package://dlr_description/meshes/hit2/medial.stl"/>
      </geometry>
    </collision>
  </link>
  <!-- outer2 joint between medial_link and distal_link -->
  <joint name="right_pinky_outer2_joint" type="revolute">
    <origin rpy="0 0 -1.57079632679" xyz="0.025 0 0"/>
    <parent link="right_pinky_medial_link"/>
    <child link="right_pinky_distal_link"/>
    <axis xyz="0 0 1"/>
    <dynamics damping="1"/>
    <limit effort="100" lower="0.0" upper="1.308996939" velocity="5"/>
    <!-- effort="100" velocity="5" -->
  </joint>
  <link name="right_pinky_distal_link">
    <!-- <inertial>
			<origin xyz="-0.83348211 6.1007977 1.7728256" rpy="0 0 0"/>
				<mass value="0.018179709"/>
				<inertia ixx="${inertia_scale * 2.5867271}" ixy="${inertia_scale * 0.15840536}" ixz="${inertia_scale * (-0.00078205885)}" iyy="${inertia_scale * 0.84596248}" iyz="${inertia_scale * (-0.0048358115)}" izz="${inertia_scale * 2.5838485}" />
			</inertial> -->
    <visual>
      <origin rpy="0 0 0" xyz="0 0 0"/>
      <geometry>
        <mesh filename="package://dlr_description/meshes/hit2/distal.stl"/>
      </geometry>
      <material name="DLR/LightGrey"/>
    </visual>
    <collision>
      <origin rpy="0 0 0" xyz="0 0 0"/>
      <geometry>
        <mesh filename="package://dlr_description/meshes/hit2/distal.stl"/>
      </geometry>
    </collision>
  </link>
  <!-- five equal fingers -->
  <transmission name="thumb_abd_trans">
    <robotNamespace>thumb</robotNamespace>
    <type>transmission_interface/SimpleTransmission</type>
    <joint name="thumb_abd_joint">
      <hardwareInterface>hardware_interface/PositionJointInterface</hardwareInterface>
      <!-- <hardwareInterface>${Interface30}</hardwareInterface> -->
    </joint>
    <actuator name="thumb_abd_motor">
      <mechanicalReduction>1.0</mechanicalReduction>
    </actuator>
  </transmission>
  <transmission name="thumb_inner_trans">
    <robotNamespace>thumb</robotNamespace>
    <type>transmission_interface/SimpleTransmission</type>
    <joint name="thumb_inner_joint">
      <hardwareInterface>hardware_interface/PositionJointInterface</hardwareInterface>
      <!-- <hardwareInterface>${Interface30}</hardwareInterface> -->
    </joint>
    <actuator name="thumb_inner_motor">
      <mechanicalReduction>1.0</mechanicalReduction>
    </actuator>
  </transmission>
  <transmission name="thumb_outer1_trans">
    <robotNamespace>thumb</robotNamespace>
    <type>transmission_interface/SimpleTransmission</type>
    <joint name="thumb_outer1_joint">
      <hardwareInterface>hardware_interface/PositionJointInterface</hardwareInterface>
      <!-- <hardwareInterface>${Interface30}</hardwareInterface> -->
    </joint>
    <actuator name="thumb_outer1_motor">
      <mechanicalReduction>1.0</mechanicalReduction>
    </actuator>
  </transmission>
  <transmission name="thumb_outer2_trans">
    <robotNamespace>thumb</robotNamespace>
    <type>transmission_interface/SimpleTransmission</type>
    <joint name="thumb_outer2_joint">
      <hardwareInterface>hardware_interface/PositionJointInterface</hardwareInterface>
      <!-- <hardwareInterface>${Interface30}</hardwareInterface> -->
    </joint>
    <actuator name="thumb_outer2_motor">
      <mechanicalReduction>1.0</mechanicalReduction>
    </actuator>
  </transmission>
  <!-- TODO: outer transmission has just one motor! -->
  <!-- one finger only -->
  <!--<transmission name="${name}_abd_trans" type="pr2_mechanism_model/SimpleTransmission">
			<actuator name="${name}_abd_motor"/>
			<joint name="${name}_abd_joint"/>
			<mechanicalReduction>1</mechanicalReduction>
		</transmission>
	
		<transmission name="${name}_inner_trans" type="pr2_mechanism_model/SimpleTransmission">
			<actuator name="${name}_inner_motor"/>
			<joint name="${name}_inner_joint"/>
			<mechanicalReduction>1</mechanicalReduction>
		</transmission>

		<transmission name="${name}_outer1_trans" type="pr2_mechanism_model/SimpleTransmission">
			<actuator name="${name}_outer1_motor"/>
			<joint name="${name}_outer1_joint"/>
			<mechanicalReduction>1</mechanicalReduction>
		</transmission>

		<transmission name="${name}_outer2_trans" type="pr2_mechanism_model/SimpleTransmission">
			<actuator name="${name}_outer2_motor"/>
			<joint name="${name}_outer2_joint"/>
			<mechanicalReduction>1</mechanicalReduction>
		</transmission>-->
  <transmission name="index_abd_trans">
    <robotNamespace>index</robotNamespace>
    <type>transmission_interface/SimpleTransmission</type>
    <joint name="index_abd_joint">
      <hardwareInterface>hardware_interface/PositionJointInterface</hardwareInterface>
      <!-- <hardwareInterface>${Interface30}</hardwareInterface> -->
    </joint>
    <actuator name="index_abd_motor">
      <mechanicalReduction>1.0</mechanicalReduction>
    </actuator>
  </transmission>
  <transmission name="index_inner_trans">
    <robotNamespace>index</robotNamespace>
    <type>transmission_interface/SimpleTransmission</type>
    <joint name="index_inner_joint">
      <hardwareInterface>hardware_interface/PositionJointInterface</hardwareInterface>
      <!-- <hardwareInterface>${Interface30}</hardwareInterface> -->
    </joint>
    <actuator name="index_inner_motor">
      <mechanicalReduction>1.0</mechanicalReduction>
    </actuator>
  </transmission>
  <transmission name="index_outer1_trans">
    <robotNamespace>index</robotNamespace>
    <type>transmission_interface/SimpleTransmission</type>
    <joint name="index_outer1_joint">
      <hardwareInterface>hardware_interface/PositionJointInterface</hardwareInterface>
      <!-- <hardwareInterface>${Interface30}</hardwareInterface> -->
    </joint>
    <actuator name="index_outer1_motor">
      <mechanicalReduction>1.0</mechanicalReduction>
    </actuator>
  </transmission>
  <transmission name="index_outer2_trans">
    <robotNamespace>index</robotNamespace>
    <type>transmission_interface/SimpleTransmission</type>
    <joint name="index_outer2_joint">
      <hardwareInterface>hardware_interface/PositionJointInterface</hardwareInterface>
      <!-- <hardwareInterface>${Interface30}</hardwareInterface> -->
    </joint>
    <actuator name="index_outer2_motor">
      <mechanicalReduction>1.0</mechanicalReduction>
    </actuator>
  </transmission>
  <!-- TODO: outer transmission has just one motor! -->
  <!-- one finger only -->
  <!--<transmission name="${name}_abd_trans" type="pr2_mechanism_model/SimpleTransmission">
			<actuator name="${name}_abd_motor"/>
			<joint name="${name}_abd_joint"/>
			<mechanicalReduction>1</mechanicalReduction>
		</transmission>
	
		<transmission name="${name}_inner_trans" type="pr2_mechanism_model/SimpleTransmission">
			<actuator name="${name}_inner_motor"/>
			<joint name="${name}_inner_joint"/>
			<mechanicalReduction>1</mechanicalReduction>
		</transmission>

		<transmission name="${name}_outer1_trans" type="pr2_mechanism_model/SimpleTransmission">
			<actuator name="${name}_outer1_motor"/>
			<joint name="${name}_outer1_joint"/>
			<mechanicalReduction>1</mechanicalReduction>
		</transmission>

		<transmission name="${name}_outer2_trans" type="pr2_mechanism_model/SimpleTransmission">
			<actuator name="${name}_outer2_motor"/>
			<joint name="${name}_outer2_joint"/>
			<mechanicalReduction>1</mechanicalReduction>
		</transmission>-->
  <transmission name="middle_abd_trans">
    <robotNamespace>middle</robotNamespace>
    <type>transmission_interface/SimpleTransmission</type>
    <joint name="middle_abd_joint">
      <hardwareInterface>hardware_interface/PositionJointInterface</hardwareInterface>
      <!-- <hardwareInterface>${Interface30}</hardwareInterface> -->
    </joint>
    <actuator name="middle_abd_motor">
      <mechanicalReduction>1.0</mechanicalReduction>
    </actuator>
  </transmission>
  <transmission name="middle_inner_trans">
    <robotNamespace>middle</robotNamespace>
    <type>transmission_interface/SimpleTransmission</type>
    <joint name="middle_inner_joint">
      <hardwareInterface>hardware_interface/PositionJointInterface</hardwareInterface>
      <!-- <hardwareInterface>${Interface30}</hardwareInterface> -->
    </joint>
    <actuator name="middle_inner_motor">
      <mechanicalReduction>1.0</mechanicalReduction>
    </actuator>
  </transmission>
  <transmission name="middle_outer1_trans">
    <robotNamespace>middle</robotNamespace>
    <type>transmission_interface/SimpleTransmission</type>
    <joint name="middle_outer1_joint">
      <hardwareInterface>hardware_interface/PositionJointInterface</hardwareInterface>
      <!-- <hardwareInterface>${Interface30}</hardwareInterface> -->
    </joint>
    <actuator name="middle_outer1_motor">
      <mechanicalReduction>1.0</mechanicalReduction>
    </actuator>
  </transmission>
  <transmission name="middle_outer2_trans">
    <robotNamespace>middle</robotNamespace>
    <type>transmission_interface/SimpleTransmission</type>
    <joint name="middle_outer2_joint">
      <hardwareInterface>hardware_interface/PositionJointInterface</hardwareInterface>
      <!-- <hardwareInterface>${Interface30}</hardwareInterface> -->
    </joint>
    <actuator name="middle_outer2_motor">
      <mechanicalReduction>1.0</mechanicalReduction>
    </actuator>
  </transmission>
  <!-- TODO: outer transmission has just one motor! -->
  <!-- one finger only -->
  <!--<transmission name="${name}_abd_trans" type="pr2_mechanism_model/SimpleTransmission">
			<actuator name="${name}_abd_motor"/>
			<joint name="${name}_abd_joint"/>
			<mechanicalReduction>1</mechanicalReduction>
		</transmission>
	
		<transmission name="${name}_inner_trans" type="pr2_mechanism_model/SimpleTransmission">
			<actuator name="${name}_inner_motor"/>
			<joint name="${name}_inner_joint"/>
			<mechanicalReduction>1</mechanicalReduction>
		</transmission>

		<transmission name="${name}_outer1_trans" type="pr2_mechanism_model/SimpleTransmission">
			<actuator name="${name}_outer1_motor"/>
			<joint name="${name}_outer1_joint"/>
			<mechanicalReduction>1</mechanicalReduction>
		</transmission>

		<transmission name="${name}_outer2_trans" type="pr2_mechanism_model/SimpleTransmission">
			<actuator name="${name}_outer2_motor"/>
			<joint name="${name}_outer2_joint"/>
			<mechanicalReduction>1</mechanicalReduction>
		</transmission>-->
  <transmission name="ring_abd_trans">
    <robotNamespace>ring</robotNamespace>
    <type>transmission_interface/SimpleTransmission</type>
    <joint name="ring_abd_joint">
      <hardwareInterface>hardware_interface/PositionJointInterface</hardwareInterface>
      <!-- <hardwareInterface>${Interface30}</hardwareInterface> -->
    </joint>
    <actuator name="ring_abd_motor">
      <mechanicalReduction>1.0</mechanicalReduction>
    </actuator>
  </transmission>
  <transmission name="ring_inner_trans">
    <robotNamespace>ring</robotNamespace>
    <type>transmission_interface/SimpleTransmission</type>
    <joint name="ring_inner_joint">
      <hardwareInterface>hardware_interface/PositionJointInterface</hardwareInterface>
      <!-- <hardwareInterface>${Interface30}</hardwareInterface> -->
    </joint>
    <actuator name="ring_inner_motor">
      <mechanicalReduction>1.0</mechanicalReduction>
    </actuator>
  </transmission>
  <transmission name="ring_outer1_trans">
    <robotNamespace>ring</robotNamespace>
    <type>transmission_interface/SimpleTransmission</type>
    <joint name="ring_outer1_joint">
      <hardwareInterface>hardware_interface/PositionJointInterface</hardwareInterface>
      <!-- <hardwareInterface>${Interface30}</hardwareInterface> -->
    </joint>
    <actuator name="ring_outer1_motor">
      <mechanicalReduction>1.0</mechanicalReduction>
    </actuator>
  </transmission>
  <transmission name="ring_outer2_trans">
    <robotNamespace>ring</robotNamespace>
    <type>transmission_interface/SimpleTransmission</type>
    <joint name="ring_outer2_joint">
      <hardwareInterface>hardware_interface/PositionJointInterface</hardwareInterface>
      <!-- <hardwareInterface>${Interface30}</hardwareInterface> -->
    </joint>
    <actuator name="ring_outer2_motor">
      <mechanicalReduction>1.0</mechanicalReduction>
    </actuator>
  </transmission>
  <!-- TODO: outer transmission has just one motor! -->
  <!-- one finger only -->
  <!--<transmission name="${name}_abd_trans" type="pr2_mechanism_model/SimpleTransmission">
			<actuator name="${name}_abd_motor"/>
			<joint name="${name}_abd_joint"/>
			<mechanicalReduction>1</mechanicalReduction>
		</transmission>
	
		<transmission name="${name}_inner_trans" type="pr2_mechanism_model/SimpleTransmission">
			<actuator name="${name}_inner_motor"/>
			<joint name="${name}_inner_joint"/>
			<mechanicalReduction>1</mechanicalReduction>
		</transmission>

		<transmission name="${name}_outer1_trans" type="pr2_mechanism_model/SimpleTransmission">
			<actuator name="${name}_outer1_motor"/>
			<joint name="${name}_outer1_joint"/>
			<mechanicalReduction>1</mechanicalReduction>
		</transmission>

		<transmission name="${name}_outer2_trans" type="pr2_mechanism_model/SimpleTransmission">
			<actuator name="${name}_outer2_motor"/>
			<joint name="${name}_outer2_joint"/>
			<mechanicalReduction>1</mechanicalReduction>
		</transmission>-->
  <transmission name="pinky_abd_trans">
    <robotNamespace>pinky</robotNamespace>
    <type>transmission_interface/SimpleTransmission</type>
    <joint name="pinky_abd_joint">
      <hardwareInterface>hardware_interface/PositionJointInterface</hardwareInterface>
      <!-- <hardwareInterface>${Interface30}</hardwareInterface> -->
    </joint>
    <actuator name="pinky_abd_motor">
      <mechanicalReduction>1.0</mechanicalReduction>
    </actuator>
  </transmission>
  <transmission name="pinky_inner_trans">
    <robotNamespace>pinky</robotNamespace>
    <type>transmission_interface/SimpleTransmission</type>
    <joint name="pinky_inner_joint">
      <hardwareInterface>hardware_interface/PositionJointInterface</hardwareInterface>
      <!-- <hardwareInterface>${Interface30}</hardwareInterface> -->
    </joint>
    <actuator name="pinky_inner_motor">
      <mechanicalReduction>1.0</mechanicalReduction>
    </actuator>
  </transmission>
  <transmission name="pinky_outer1_trans">
    <robotNamespace>pinky</robotNamespace>
    <type>transmission_interface/SimpleTransmission</type>
    <joint name="pinky_outer1_joint">
      <hardwareInterface>hardware_interface/PositionJointInterface</hardwareInterface>
      <!-- <hardwareInterface>${Interface30}</hardwareInterface> -->
    </joint>
    <actuator name="pinky_outer1_motor">
      <mechanicalReduction>1.0</mechanicalReduction>
    </actuator>
  </transmission>
  <transmission name="pinky_outer2_trans">
    <robotNamespace>pinky</robotNamespace>
    <type>transmission_interface/SimpleTransmission</type>
    <joint name="pinky_outer2_joint">
      <hardwareInterface>hardware_interface/PositionJointInterface</hardwareInterface>
      <!-- <hardwareInterface>${Interface30}</hardwareInterface> -->
    </joint>
    <actuator name="pinky_outer2_motor">
      <mechanicalReduction>1.0</mechanicalReduction>
    </actuator>
  </transmission>
  <!-- TODO: outer transmission has just one motor! -->
  <!-- one finger only -->
  <!--<transmission name="${name}_abd_trans" type="pr2_mechanism_model/SimpleTransmission">
			<actuator name="${name}_abd_motor"/>
			<joint name="${name}_abd_joint"/>
			<mechanicalReduction>1</mechanicalReduction>
		</transmission>
	
		<transmission name="${name}_inner_trans" type="pr2_mechanism_model/SimpleTransmission">
			<actuator name="${name}_inner_motor"/>
			<joint name="${name}_inner_joint"/>
			<mechanicalReduction>1</mechanicalReduction>
		</transmission>

		<transmission name="${name}_outer1_trans" type="pr2_mechanism_model/SimpleTransmission">
			<actuator name="${name}_outer1_motor"/>
			<joint name="${name}_outer1_joint"/>
			<mechanicalReduction>1</mechanicalReduction>
		</transmission>

		<transmission name="${name}_outer2_trans" type="pr2_mechanism_model/SimpleTransmission">
			<actuator name="${name}_outer2_motor"/>
			<joint name="${name}_outer2_joint"/>
			<mechanicalReduction>1</mechanicalReduction>
		</transmission>-->
</robot>

